<?xml version="1.0" encoding="utf-8"?>
<sdf version='1.6'>
  <model name='spbot'>
    <link name='chassis'>
      <pose frame=''>0 0 0 0 -0 0</pose>
      <inertial>
        <pose frame=''>0.15 0 0.116667 0 -0 0</pose>
        <mass>9.6</mass>
        <inertia>
          <ixx>0.557333</ixx>
          <ixy>0</ixy>
          <ixz>0.6</ixz>
          <iyy>1.57333</iyy>
          <iyz>-6.93889e-18</iyz>
          <izz>1.304</izz>
        </inertia>
      </inertial>
      <collision name='chassis_fixed_joint_lump__collision_collision'>
        <pose frame=''>0 0 0 0 -0 0</pose>
        <geometry>
          <box>
            <size>0.8 0.5 0.22</size>
          </box>
        </geometry>
      </collision>
      <collision name='chassis_fixed_joint_lump__collision_collision_1'>
        <pose frame=''>0.9 0.2 -0.3 0 -0 0</pose>
        <geometry>
          <mesh>
            <scale>1 1 1</scale>
            <uri>file:///home/rit/catkin_ws2/src/spbot/spbot_description/meshes/free_wheel.dae</uri>
          </mesh>
        </geometry>
      </collision>
      <collision name='chassis_fixed_joint_lump__collision_collision_2'>
        <pose frame=''>0.9 -0.2 -0.3 0 -0 0</pose>
        <geometry>
          <mesh>
            <scale>1 1 1</scale>
            <uri>file:///home/rit/catkin_ws2/src/spbot/spbot_description/meshes/free_wheel.dae</uri>
          </mesh>
        </geometry>
      </collision>
      <visual name='chassis_visual_visual'>
        <pose frame=''>0 0 0.1 0 -0 0</pose>
        <geometry>
          <box>
            <size>0.8 0.5 0.22</size>
          </box>
        </geometry>
      </visual>
      <visual name='chassis_fixed_joint_lump__visual_visual_1'>
        <pose frame=''>0.9 0.2 -0.3 0 -0 0</pose>
        <geometry>
          <mesh>
            <scale>1 1 1</scale>
            <uri>file:///home/rit/catkin_ws2/src/spbot/spbot_description/meshes/free_wheel.dae</uri>
          </mesh>
        </geometry>
      </visual>
      <visual name='chassis_fixed_joint_lump__visual_visual_2'>
        <pose frame=''>0.9 -0.2 -0.3 0 -0 0</pose>
        <geometry>
          <mesh>
            <scale>1 1 1</scale>
            <uri>file:///home/rit/catkin_ws2/src/spbot/spbot_description/meshes/free_wheel.dae</uri>
          </mesh>
        </geometry>
      </visual>
    </link>
    <link name='left_wheel'>
      <pose frame=''>0.18 0.26 0.08 0 -0 0</pose>
      <inertial>
        <pose frame=''>0 0 0 0 1.5707 1.5707</pose>
        <mass>1</mass>
        <inertia>
          <ixx>0.1</ixx>
          <ixy>0</ixy>
          <ixz>0</ixz>
          <iyy>0.1</iyy>
          <iyz>0</iyz>
          <izz>0.1</izz>
        </inertia>
      </inertial>
      <collision name='left_wheel_fixed_joint_lump__collision_collision'>
        <pose frame=''>0 0 0 3.14159 1.57079 -1.57089</pose>
        <geometry>
          <cylinder>
            <length>0.05</length>
            <radius>0.2</radius>
          </cylinder>
        </geometry>
      </collision>
      <visual name='left_wheel_visual_visual'>
        <pose frame=''>0 0 0 3.14159 1.57079 -1.57089</pose>
        <geometry>
          <cylinder>
            <length>0.05</length>
            <radius>0.2</radius>
          </cylinder>
        </geometry>
      </visual>
    </link>
    <joint name='wheel_left_joint' type='revolute'>
      <child>left_wheel</child>
      <parent>chassis</parent>
      <axis>
        <xyz>0 1 0</xyz>
        <limit>
          <lower>-1e+16</lower>
          <upper>1e+16</upper>
        </limit>
        <dynamics>
          <spring_reference>0</spring_reference>
          <spring_stiffness>0</spring_stiffness>
        </dynamics>
        <use_parent_model_frame>1</use_parent_model_frame>
      </axis>
    </joint>
    <link name='right_wheel'>
      <pose frame=''>0.18 -0.26 0.08 0 -0 0</pose>
      <inertial>
        <pose frame=''>0 0 0 0 1.5707 1.5707</pose>
        <mass>1</mass>
        <inertia>
          <ixx>0.1</ixx>
          <ixy>0</ixy>
          <ixz>0</ixz>
          <iyy>0.1</iyy>
          <iyz>0</iyz>
          <izz>0.1</izz>
        </inertia>
      </inertial>
      <collision name='right_wheel_fixed_joint_lump__collision_collision'>
        <pose frame=''>0 0 0 3.14159 1.57079 -1.57089</pose>
        <geometry>
          <cylinder>
            <length>0.05</length>
            <radius>0.2</radius>
          </cylinder>
        </geometry>
      </collision>
      <visual name='right_wheel_visual_visual'>
        <pose frame=''>0 0 0 3.14159 1.57079 -1.57089</pose>
        <geometry>
          <cylinder>
            <length>0.05</length>
            <radius>0.2</radius>
          </cylinder>
        </geometry>
      </visual>
    </link>
    <joint name='wheel_right_joint' type='revolute'>
      <child>right_wheel</child>
      <parent>chassis</parent>
      <axis>
        <xyz>0 1 0</xyz>
        <limit>
          <lower>-1e+16</lower>
          <upper>1e+16</upper>
        </limit>
        <dynamics>
          <spring_reference>0</spring_reference>
          <spring_stiffness>0</spring_stiffness>
        </dynamics>
        <use_parent_model_frame>1</use_parent_model_frame>
      </axis>
    </joint>
    <static>0</static>
    <plugin name='gazebo_ros_control' filename='libgazebo_ros_control.so'>
      <robotNamespace>/spbot</robotNamespace>
    </plugin>
    <plugin name='differential_drive_controller' filename='libgazebo_ros_diff_drive.so'>
      <robotSimType>gazebo_ros_control/DefaultRobotHWSim</robotSimType>
      <alwaysOn>1</alwaysOn>
      <updateRate>20</updateRate>
      <leftJoint>wheel_left_joint</leftJoint>
      <rightJoint>wheel_right_joint</rightJoint>
      <wheelSeparation>0.5380</wheelSeparation>
      <wheelDiameter>0.2410</wheelDiameter>
      <torque>20</torque>
      <commandTopic>cmd_vel</commandTopic>
      <odometryTopic>odom</odometryTopic>
      <odometryFrame>odom</odometryFrame>
      <odometrySource>world</odometrySource>
      <publishTf>1</publishTf>
      <robotBaseFrame>chassis</robotBaseFrame>
      <publishWheelTF>1</publishWheelTF>
      <publishOdomTF>1</publishOdomTF>
      <publishWheelJointState>1</publishWheelJointState>
      <wheelAcceleration>0</wheelAcceleration>
      <wheelTorque>5</wheelTorque>
      <rosDebugLevel>na</rosDebugLevel>
    </plugin>


     <sensor name='chassis_contact' type='contact'>
       <!--selfCollide>true</selfCollide-->
       <alwaysOn>true</alwaysOn>
       <updateRate>15.0</updateRate>
       <!--material>Gazebo/Red</material-->

       <contact>
         <collision>chassis_fixed_joint_lump__collision_collision</collision>
       </contact>
       <topic>__default_topic__</topic>

      <plugin name="gazebo_ros_bumper_controller" filename="libgazebo_ros_bumper.so">
        <bumperTopicName>chassis_contact_info</bumperTopicName>
         <frameName>chassis</frameName>
       </plugin>
     </sensor>


  </model>
</sdf>
