<?xml version="1.0" encoding="utf-8"?>
<!-- =================================================================================== -->
<!-- |    This document was autogenerated by xacro from spbot.urdf.xacro               | -->
<!-- |    EDITING THIS FILE BY HAND IS NOT RECOMMENDED                                 | -->
<!-- =================================================================================== -->
<robot name="spbot" xmlns:xacro="http://www.ros.org/wiki/xacro">
  <!--///////////////////////////////////////////////////////////////////////////////////////////////////////////////////////////////////////////////////////-->
  <link name="chassis">
    <!--pose> 0 0 0.2 0 0 0</pose-->
    <inertial>
      <mass value="8.0"/>
      <origin rpy="0 0 0" xyz="0.0 0 0.2"/>
      <inertia ixx="0.08" ixy="0" ixz="0" iyy="0.08" iyz="0" izz="0.08"/>
    </inertial>
    <collision name="collision">
      <geometry>
        <box size="0.8 .5 .22"/>
      </geometry>
    </collision>
    <visual name="visual">
      <origin rpy="0 0 0" xyz="0 0 0.1"/>
      <geometry>
        <box size="0.8 .5 .22"/>
      </geometry>
    </visual>
  </link>
  <!--left_free_wheel_link-->
  <link name="left_free_wheel">
    <collision name="collision">
      <origin rpy="0 0 0" xyz="0.9 0.1 -0.6"/>
      <geometry>
        <mesh filename="file:///home/rit/catkin_ws2/src/spbot/spbot_description/meshes/free_wheel.dae"/>
      </geometry>
    </collision>
    <visual name="visual">
      <origin rpy="0 0 0" xyz="0.9 0.1 -0.6"/>
      <geometry>
        <mesh filename="file:///home/rit/catkin_ws2/src/spbot/spbot_description/meshes/free_wheel.dae"/>
      </geometry>
    </visual>
    <inertial>
      <origin rpy="0 -0 0" xyz="0.9 0.1 -0.6"/>
      <mass value="0.8"/>
      <inertia ixx="0.04" ixy="0" ixz="0" iyy="0.04" iyz="0" izz="0.04"/>
    </inertial>
  </link>
  <!--right_free_wheel_link-->
  <link name="right_free_wheel">
    <collision name="collision">
      <origin rpy="0 0 0" xyz="0.9 -0.1 -0.6"/>
      <geometry>
        <mesh filename="file:///home/rit/catkin_ws2/src/spbot/spbot_description/meshes/free_wheel.dae"/>
      </geometry>
    </collision>
    <visual name="visual">
      <origin rpy="0 0 0" xyz="0.9 -0.1 -0.6"/>
      <geometry>
        <mesh filename="file:///home/rit/catkin_ws2/src/spbot/spbot_description/meshes/free_wheel.dae"/>
      </geometry>
    </visual>
    <inertial>
      <origin rpy="0 -0 0" xyz="0.9 -0.1 -0.6"/>
      <mass value="0.8"/>
      <inertia ixx="0.04" ixy="0" ixz="0" iyy="0.04" iyz="0" izz="0.04"/>
    </inertial>
  </link>
  <!--left_wheel-->
  <link name="left_wheel">
    <collision name="collision">
      <origin rpy="0 1.5707 1.5707" xyz="0 0 0"/>
      <geometry>
        <cylinder length="0.05" radius="0.2"/>
      </geometry>
    </collision>
    <visual name="left_wheel_visual">
      <origin rpy="0 1.5707 1.5707" xyz="0 0 0"/>
      <geometry>
        <cylinder length="0.05" radius="0.2"/>
      </geometry>
    </visual>
    <inertial>
      <origin rpy="0 1.5707 1.5707" xyz="0 0 0"/>
      <mass value="1.0"/>
      <inertia ixx=".1" ixy="0.0" ixz="0.0" iyy=".1" iyz="0.0" izz=".1"/>
    </inertial>
  </link>
  <!--right_wheel-->
  <link name="right_wheel">
    <collision name="collision">
      <origin rpy="0 1.5707 1.5707" xyz="0 0 0"/>
      <geometry>
        <cylinder length="0.05" radius="0.2"/>
      </geometry>
    </collision>
    <visual name="right_wheel_visual">
      <origin rpy="0 1.5707 1.5707" xyz="0 0 0"/>
      <geometry>
        <cylinder length="0.05" radius="0.2"/>
      </geometry>
    </visual>
    <inertial>
      <origin rpy="0 1.5707 1.5707" xyz="0 0 0"/>
      <mass value="1.0"/>
      <inertia ixx=".1" ixy="0.0" ixz="0.0" iyy=".1" iyz="0.0" izz=".1"/>
    </inertial>
  </link>
  <!--left_wheel_joint-->
  <joint name="wheel_left_joint" type="continuous">
    <origin rpy="0 0 0" xyz="0.18 0.26 0.08"/>
    <child link="left_wheel"/>
    <parent link="chassis"/>
    <axis rpy="0 0 0" xyz="0 1 0"/>
    <limit effort="10000" velocity="1000"/>
    <joint_properties damping="1.0" friction="1.0"/>
  </joint>
  <!--right_wheel_joint-->
  <joint name="wheel_right_joint" type="continuous">
    <origin rpy="0 0 0" xyz="0.18 -0.26 0.08"/>
    <child link="right_wheel"/>
    <parent link="chassis"/>
    <axis rpy="0 0 0" xyz="0 1 0"/>
    <limit effort="10000" velocity="1000"/>
    <joint_properties damping="1.0" friction="1.0"/>
  </joint>
  <!--left_free_wheel_hinge-->
  <joint name="left_free_wheel_hinge" type="fixed">
    <origin rpy="0 0 0" xyz="0.0 0.1 0.3"/>
    <child link="left_free_wheel"/>
    <parent link="chassis"/>
    <axis rpy="0 0 0" xyz="0 1 0"/>
    <limit effort="10000" velocity="1000"/>
    <joint_properties damping="1.0" friction="1.0"/>
  </joint>
  <!--right_free_wheel hinge-->
  <joint name="right_free_wheel_hinge" type="fixed">
    <origin rpy="0 0 0" xyz="0.0 -0.1 0.3"/>
    <child link="right_free_wheel"/>
    <parent link="chassis"/>
    <axis rpy="0 0 0" xyz="0 1 0"/>
    <limit effort="10000" velocity="1000"/>
    <joint_properties damping="1.0" friction="1.0"/>
  </joint>

<gazebo reference="chassis">
    <sensor name="contactsensor_sensor" type="contact">
      <always_on>true</always_on>
      <updateRate>15.0</updateRate>
      <contact>
        <collision>chassis_fixed_joint_lump__collision_collision</collision>
      </contact>
      <plugin filename="libgazebo_ros_bumper.so" name="gazebo_ros_bumper_controller">
        <bumperTopicName>chassis_contact_info</bumperTopicName>
        <frameName>chassis</frameName>
      </plugin>
    </sensor>
  </gazebo>

  <!--gazebo-ros plugin differential drive-->
  <gazebo>
    <plugin filename="libgazebo_ros_control.so" name="gazebo_ros_control">
      <robotNamespace>/spbot</robotNamespace>
    </plugin>
    <plugin filename="libgazebo_ros_diff_drive.so" name="differential_drive_controller">
      <robotSimType>gazebo_ros_control/DefaultRobotHWSim</robotSimType>
      <alwaysOn>true</alwaysOn>
      <updateRate>20</updateRate>
      <leftJoint>wheel_left_joint</leftJoint>
      <rightJoint>wheel_right_joint</rightJoint>
      <wheelSeparation>0.5380</wheelSeparation>
      <wheelDiameter>0.2410</wheelDiameter>
      <torque>20</torque>
      <commandTopic>cmd_vel</commandTopic>
      <odometryTopic>odom</odometryTopic>
      <odometryFrame>odom</odometryFrame>
      <odometrySource>world</odometrySource>
      <publishTf>1</publishTf>
      <robotBaseFrame>chassis</robotBaseFrame>
      <publishWheelTF>true</publishWheelTF>
      <publishOdomTF>true</publishOdomTF>
      <publishWheelJointState>true</publishWheelJointState>
      <wheelAcceleration>0</wheelAcceleration>
      <wheelTorque>5</wheelTorque>
      <rosDebugLevel>na</rosDebugLevel>
    </plugin>
  </gazebo>
</robot>
